<?xml version='1.0'?>
<robot name="dd_robot">

  <!-- Base Link -->
  <link name="base_link">
    <visual>
      <origin xyz="0 0 0" rpy="0 0 0" />
      <geometry>
          <box size="2.0 0.8 0.25"/>
      </geometry>
      <material name="blue">
        <color rgba="0 0.5 1 1"/>
      </material>
    </visual>

    <!-- Base Collision -->
    <collision>
      <origin xyz="0 0 0" rpy="0 0 0" />
      <geometry>
        <box size="2.0 0.8 0.25" />
      </geometry>
    </collision>

    <inertial>
      <mass value="5" />
      <inertia ixx="0.13" ixy="0.0" ixz="0.0"
                iyy="0.21" iyz="0.0" izz="0.13" />
    </inertial>

  </link>

  <gazebo reference="base_link">
    <material>Gazebo/Blue</material>
    <pose>0 0 3 0 0 0</pose>
  </gazebo>

  <!-- Right Wheel1 -->
  <link name="right_wheel1">
    <visual>
      <origin xyz="0 0 0" rpy="1.570795 0 0" />
      <geometry>
          <cylinder length="0.1" radius="0.2" />
      </geometry>
      <material name="black">
        <color rgba="0.05 0.05 0.05 1"/>
      </material>
    </visual>
    
    <collision>
      <origin xyz="0 0 0" rpy="1.570795 0 0" />
      <geometry>
        <cylinder length="0.1" radius="0.2" />
      </geometry>
    </collision>

    <inertial>
      <mass value="0.5" />
      <inertia ixx="0.01" ixy="0.0" ixz="0.0"
               iyy="0.005" iyz="0.0" izz="0.005" />
    </inertial>

  </link>
  
  <gazebo reference="right_wheel1">
    <material>Gazebo/Black</material>
  </gazebo>

  <joint name="joint_right_wheel1" type="continuous">
    <parent link="base_link"/>
    <child link="right_wheel1"/>
    <origin xyz="0.8 -0.45 0" rpy="0 0 0" /> 
    <axis xyz="0 1 0" />
  </joint>

  <!-- Left Wheel1 -->
  <link name="left_wheel1">
    <visual>
      <origin xyz="0 0 0" rpy="1.570795 0 0" />
      <geometry>
          <cylinder length="0.1" radius="0.2" />
      </geometry>
      <material name="black"/>
    </visual>

    <collision>
      <origin xyz="0 0 0" rpy="1.570795 0 0" />
      <geometry>
        <cylinder length="0.1" radius="0.2" />
      </geometry>
    </collision>

    <inertial>
      <mass value="0.5" />
      <inertia ixx="0.01" ixy="0.0" ixz="0.0"
               iyy="0.005" iyz="0.0" izz="0.005" />
    </inertial>

  </link>

  <gazebo reference="left_wheel1">
    <material>Gazebo/Black</material>
  </gazebo>

  <joint name="joint_left_wheel1" type="continuous">
    <parent link="base_link"/>
    <child link="left_wheel1"/>
    <origin xyz="0.8 0.45 0" rpy="0 0 0" /> 
    <axis xyz="0 1 0" />
  </joint>

  <!-- Right Wheel2 -->
  <link name="right_wheel2">
    <visual>
      <origin xyz="0 0 0" rpy="1.570795 0 0" />
      <geometry>
          <cylinder length="0.1" radius="0.2" />
      </geometry>
      <material name="black">
        <color rgba="0.05 0.05 0.05 1"/>
      </material>
    </visual>

    <collision>
      <origin xyz="0 0 0" rpy="1.570795 0 0" />
      <geometry>
        <cylinder length="0.1" radius="0.2" />
      </geometry>
    </collision>

    <inertial>
      <mass value="0.5" />
      <inertia ixx="0.01" ixy="0.0" ixz="0.0"
               iyy="0.005" iyz="0.0" izz="0.005" />
    </inertial>

  </link>

  <gazebo reference="right_wheel2">
    <material>Gazebo/Black</material>
  </gazebo>

  <joint name="joint_right_wheel2" type="continuous">
    <parent link="base_link"/>
    <child link="right_wheel2"/>
    <origin xyz="0 -0.45 0" rpy="0 0 0" /> 
    <axis xyz="0 1 0" />
  </joint>

  <!-- Left Wheel2 -->
  <link name="left_wheel2">
    <visual>
      <origin xyz="0 0 0" rpy="1.570795 0 0" />
      <geometry>
          <cylinder length="0.1" radius="0.2" />
      </geometry>
      <material name="black"/>
    </visual>

    <collision>
      <origin xyz="0 0 0" rpy="1.570795 0 0" />
      <geometry>
        <cylinder length="0.1" radius="0.2" />
      </geometry>
    </collision>

    <inertial>
      <mass value="0.5" />
      <inertia ixx="0.01" ixy="0.0" ixz="0.0"
               iyy="0.005" iyz="0.0" izz="0.005" />
    </inertial>

  </link>

  <gazebo reference="left_wheel2">
    <material>Gazebo/Black</material>
  </gazebo>

  <joint name="joint_left_wheel2" type="continuous">
    <parent link="base_link"/>
    <child link="left_wheel2"/>
    <origin xyz="0 0.45 0" rpy="0 0 0" /> 
    <axis xyz="0 1 0" />
  </joint>

  <!-- Right Wheel3 -->
  <link name="right_wheel3">
    <visual>
      <origin xyz="0 0 0" rpy="1.570795 0 0" />
      <geometry>
          <cylinder length="0.1" radius="0.2" />
      </geometry>
      <material name="black">
        <color rgba="0.05 0.05 0.05 1"/>
      </material>
    </visual>

    <collision>
      <origin xyz="0 0 0" rpy="1.570795 0 0" />
      <geometry>
        <cylinder length="0.1" radius="0.2" />
      </geometry>
    </collision>

    <inertial>
      <mass value="0.5" />
      <inertia ixx="0.01" ixy="0.0" ixz="0.0"
               iyy="0.005" iyz="0.0" izz="0.005" />
    </inertial>

  </link>

  <gazebo reference="right_wheel3">
    <material>Gazebo/Black</material>
  </gazebo>

  <joint name="joint_right_wheel3" type="continuous">
    <parent link="base_link"/>
    <child link="right_wheel3"/>
    <origin xyz="-0.8 -0.45 0" rpy="0 0 0" /> 
    <axis xyz="0 1 0" />
  </joint>

  <!-- Left Wheel3 -->
  <link name="left_wheel3">
    <visual>
      <origin xyz="0 0 0" rpy="1.570795 0 0" />
      <geometry>
          <cylinder length="0.1" radius="0.2" />
      </geometry>
      <material name="black"/>
    </visual>

    <collision>
      <origin xyz="0 0 0" rpy="1.570795 0 0" />
      <geometry>
        <cylinder length="0.1" radius="0.2" />
      </geometry>
    </collision>

    <inertial>
      <mass value="0.5" />
      <inertia ixx="0.01" ixy="0.0" ixz="0.0"
               iyy="0.005" iyz="0.0" izz="0.005" />
    </inertial>

  </link>

  <gazebo reference="left_wheel3">
    <material>Gazebo/Black</material>
  </gazebo>

  <joint name="joint_left_wheel3" type="continuous">
    <parent link="base_link"/>
    <child link="left_wheel3"/>
    <origin xyz="-0.8 0.45 0" rpy="0 0 0" /> 
    <axis xyz="0 1 0" />
  </joint>

</robot>
