<?xml version="1.0"?>
<robot name="mrobot" xmlns:xacro="http://www.ros.org/wiki/xacro">

    <!-- Defining the colors used in this robot -->
    <material name="Black">
        <color rgba="0 0 0 1"/>
    </material>

    <material name="White">
        <color rgba="1 1 1 1"/>
    </material>

    <material name="Blue">
        <color rgba="0 0 1 1"/>
    </material>

    <material name="Red">
        <color rgba="1 0 0 1"/>
    </material>

    <!-- PROPERTY LIST -->
    <!--All units in m-kg-s-radians unit system -->
    <xacro:property name="M_PI" value="3.1415926535897931" />

    <!-- Main body length, width, height and mass -->
    <xacro:property name="base_mass"       value="0.5" /> 
    <xacro:property name="base_link_size"  value="2.0 0.8 0.2" />
    <xacro:property name="base_link_width" value="0.8" />

    <!-- Wheel radius, height and mass -->
    <xacro:property name="wheel_radius" value="0.2" /> 
    <xacro:property name="wheel_height" value="0.1" />
    <xacro:property name="wheel_mass"   value="0.1" />

    <!-- Macro for inertia matrix -->
    <xacro:macro name="sphere_inertial_matrix" params="m r">
        <inertial>
            <mass value="${m}" />
            <inertia ixx="${2*m*r*r/5}" ixy="0" ixz="0"
                iyy="${2*m*r*r/5}" iyz="0" 
                izz="${2*m*r*r/5}" />
        </inertial>
    </xacro:macro>

    <xacro:macro name="cylinder_inertial_matrix" params="m r h">
        <inertial>
            <mass value="${m}" />
            <inertia ixx="${m*(3*r*r+h*h)/12}" ixy = "0" ixz = "0"
                iyy="${m*(3*r*r+h*h)/12}" iyz = "0"
                izz="${m*r*r/2}" /> 
        </inertial>
    </xacro:macro>

    <xacro:macro name="box_inertial_matrix" params="m">
        <inertial>
            <mass value="${m}" />
            <inertia ixx="0.13" ixy = "0.0" ixz = "0.0"
                     iyy="0.21" iyz = "0.0" izz="0.13" /> 
        </inertial>
    </xacro:macro>

    <!-- Macro for wheel joint -->
    <xacro:macro name="wheel" params="lr motor_x translateY">
        <!-- lr: left, right -->
        <link name="wheel_${lr}_link">
            <visual>
                <origin xyz="0 0 0" rpy="${M_PI/2} 0  0 " /> 
                <geometry>
                    <cylinder length="${wheel_height}" radius="${wheel_radius}" />
                </geometry>
                <material name="Black" />
            </visual>
            <collision>
                <origin xyz="0 0 0" rpy="${M_PI/2} 0 0 " />
                <geometry>
                    <cylinder length="${wheel_height}" radius="${wheel_radius}" />
                </geometry>
            </collision>
            <cylinder_inertial_matrix  m="${wheel_mass}" r="${wheel_radius}" h="${wheel_height}" />
        </link>

        <gazebo reference="wheel_${lr}_link">
            <material>Gazebo/Black</material>
        </gazebo>

        <joint name="base_to_wheel_${lr}_joint" type="continuous">
            <parent link="base_link"/>
            <child link="wheel_${lr}_link"/>
            <origin xyz="${motor_x} ${translateY} 0" rpy="0 0 0" /> 
            <axis xyz="0 1 0" rpy="0  0" />
        </joint>

        <!-- Transmission is important to link the joints and the controller -->
        <transmission name="wheel_${lr}_joint_trans">
            <type>transmission_interface/SimpleTransmission</type>
            <joint name="base_to_wheel_${lr}_joint" />
            <actuator name="wheel_${lr}_joint_motor">
                <hardwareInterface>VelocityJointInterface</hardwareInterface>
                <mechanicalReduction>1</mechanicalReduction>
            </actuator>
        </transmission>
    </xacro:macro>

    <!-- BASE-FOOTPRINT -->
    <!-- base_footprint is a fictitious link(frame) that is on the ground right below base_link origin -->
    <xacro:macro name="mrobot_body">
        <link name="base_footprint">
            <visual>
                <origin xyz="0 0 0" rpy="0 0 0" />
                <geometry>
                    <box size="0.001 0.001 0.001" />
                </geometry>
            </visual>
        </link>

        <joint name="base_footprint_joint" type="fixed">
            <origin xyz="0 0 ${wheel_radius}" rpy="0 0 0" />
            <parent link="base_footprint"/>
            <child link="base_link" />
        </joint>

        <!-- BASE-LINK -->
        <!--Actual body/chassis of the robot-->
        <link name="base_link">
            <box_inertial_matrix  m="${base_mass}" />
            <visual>
                <origin xyz=" 0 0 0" rpy="0 0 0" />
                <geometry>
                    <box size="2.0 0.8 0.25"/>
                </geometry>
                <material name="yellow" />
            </visual>

            <collision>
                <origin xyz="0 0 0" rpy="0 0 0" />
                <geometry>
                    <box size="${base_link_size}" />
                </geometry>
            </collision>   
        </link>
        <gazebo reference="base_link">
            <material>Gazebo/Blue</material>
        </gazebo>

        <!-- Wheel Definitions -->
        <wheel lr="right1"  motor_x="0.8" translateY="-0.45" />
        <wheel lr="left1"  motor_x="0.8" translateY="0.45" />
        <wheel lr="right2"  motor_x="0" translateY="-0.45" />
        <wheel lr="left2"  motor_x="0" translateY="0.45" />
        <wheel lr="right3"  motor_x="-0.8" translateY="-0.45" />
        <wheel lr="left3"  motor_x="-0.8" translateY="0.45" />

        <!-- controller -->
        <gazebo>
            <!--plugin name="differential_drive_controller" filename="libgazebo_ros_diff_drive.so">
                <rosDebugLevel>Debug</rosDebugLevel>
                <publishWheelTF>true</publishWheelTF>
                <robotNamespace>/</robotNamespace>
                <publishTf>1</publishTf>
                <publishWheelJointState>true</publishWheelJointState>
                <alwaysOn>true</alwaysOn>
                <updateRate>100.0</updateRate>
                <legacyMode>true</legacyMode>
                <leftJoint>base_to_wheel_left1_joint</leftJoint>
                <rightJoint>base_to_wheel_right2_joint</rightJoint>
                <wheelSeparation>0.8</wheelSeparation>
                <wheelDiameter>0.4</wheelDiameter>
                <broadcastTF>1</broadcastTF>
                <wheelTorque>30</wheelTorque>
                <wheelAcceleration>1.8</wheelAcceleration>
                <commandTopic>cmd_vel</commandTopic>
                <odometryFrame>odom</odometryFrame> 
                <odometryTopic>odom</odometryTopic> 
                <odometrySource>1</odometrySource>
                <robotBaseFrame>base_footprint</robotBaseFrame>
            </plugin-->
            <plugin name="diffdrive_plugin_multiwheel" filename="libdiffdrive_plugin_multi_wheel.so">
                <alwaysOn>true</alwaysOn>
                <updateRate>100</updateRate>
                <leftJoints> base_to_wheel_right1_joint base_to_wheel_right2_joint base_to_wheel_right3_joint </leftJoints>
                <rightJoints> base_to_wheel_left1_joint base_to_wheel_left2_joint base_to_wheel_left3_joint </rightJoints>
                <wheelSeparation>0.8</wheelSeparation>
                <wheelDiameter>0.4</wheelDiameter>
                <torque>500</torque>
                <robotNamespace>/</robotNamespace>
                <robotBaseFrame>base_link</robotBaseFrame>
                <commandTopic>/cmd_vel</commandTopic>
                <publishOdometryTf>0</publishOdometryTf>
                <publishOdometryMsg>1</publishOdometryMsg>
            </plugin>
        </gazebo>

    </xacro:macro>
</robot>
